Traceback (most recent call last):
  File "/home/conda/hytest/738ff346-1752093942-203-pangeo/lib/python3.11/site-packages/jupyter_core/utils/__init__.py", line 154, in wrapped
    asyncio.get_running_loop()
RuntimeError: no running event loop

During handling of the above exception, another exception occurred:

Traceback (most recent call last):
  File "/home/conda/hytest/738ff346-1752093942-203-pangeo/lib/python3.11/site-packages/jupyter_cache/executors/utils.py", line 58, in single_nb_execution
    executenb(
  File "/home/conda/hytest/738ff346-1752093942-203-pangeo/lib/python3.11/site-packages/nbclient/client.py", line 1319, in execute
    return NotebookClient(nb=nb, resources=resources, km=km, **kwargs).execute()
           ^^^^^^^^^^^^^^^^^^^^^^^^^^^^^^^^^^^^^^^^^^^^^^^^^^^^^^^^^^^^^^^^^^^^^
  File "/home/conda/hytest/738ff346-1752093942-203-pangeo/lib/python3.11/site-packages/jupyter_core/utils/__init__.py", line 158, in wrapped
    return loop.run_until_complete(inner)
           ^^^^^^^^^^^^^^^^^^^^^^^^^^^^^^
  File "/home/conda/hytest/738ff346-1752093942-203-pangeo/lib/python3.11/asyncio/base_events.py", line 654, in run_until_complete
    return future.result()
           ^^^^^^^^^^^^^^^
  File "/home/conda/hytest/738ff346-1752093942-203-pangeo/lib/python3.11/site-packages/nbclient/client.py", line 709, in async_execute
    await self.async_execute_cell(
  File "/home/conda/hytest/738ff346-1752093942-203-pangeo/lib/python3.11/site-packages/nbclient/client.py", line 1062, in async_execute_cell
    await self._check_raise_for_error(cell, cell_index, exec_reply)
  File "/home/conda/hytest/738ff346-1752093942-203-pangeo/lib/python3.11/site-packages/nbclient/client.py", line 918, in _check_raise_for_error
    raise CellExecutionError.from_cell_and_msg(cell, exec_reply_content)
nbclient.exceptions.CellExecutionError: An error occurred while executing the following cell:
------------------
# Set up a dask bag with the contents beging a list of the cobalt gages
import dask.bag as db
bag = db.from_sequence( cobalt.index.tolist() ).map(compute_benchmark)

results = bag.compute() #<< Dispatch the workers
------------------


[31m---------------------------------------------------------------------------[39m
[31mFutureCancelledError[39m                      Traceback (most recent call last)
[36mCell[39m[36m [39m[32mIn[12][39m[32m, line 5[39m
[32m      2[39m [38;5;28;01mimport[39;00m[38;5;250m [39m[34;01mdask[39;00m[34;01m.[39;00m[34;01mbag[39;00m[38;5;250m [39m[38;5;28;01mas[39;00m[38;5;250m [39m[34;01mdb[39;00m
[32m      3[39m bag = db.from_sequence( cobalt.index.tolist() ).map(compute_benchmark)
[32m----> [39m[32m5[39m results = [43mbag[49m[43m.[49m[43mcompute[49m[43m([49m[43m)[49m [38;5;66;03m#<< Dispatch the workers[39;00m

[36mFile [39m[32m/home/conda/hytest/738ff346-1752093942-203-pangeo/lib/python3.11/site-packages/dask/base.py:373[39m, in [36mDaskMethodsMixin.compute[39m[34m(self, **kwargs)[39m
[32m    349[39m [38;5;28;01mdef[39;00m[38;5;250m [39m[34mcompute[39m([38;5;28mself[39m, **kwargs):
[32m    350[39m [38;5;250m    [39m[33;03m"""Compute this dask collection[39;00m
[32m    351[39m 
[32m    352[39m [33;03m    This turns a lazy Dask collection into its in-memory equivalent.[39;00m
[32m   (...)[39m[32m    371[39m [33;03m    dask.compute[39;00m
[32m    372[39m [33;03m    """[39;00m
[32m--> [39m[32m373[39m     (result,) = [43mcompute[49m[43m([49m[38;5;28;43mself[39;49m[43m,[49m[43m [49m[43mtraverse[49m[43m=[49m[38;5;28;43;01mFalse[39;49;00m[43m,[49m[43m [49m[43m*[49m[43m*[49m[43mkwargs[49m[43m)[49m
[32m    374[39m     [38;5;28;01mreturn[39;00m result

[36mFile [39m[32m/home/conda/hytest/738ff346-1752093942-203-pangeo/lib/python3.11/site-packages/dask/base.py:681[39m, in [36mcompute[39m[34m(traverse, optimize_graph, scheduler, get, *args, **kwargs)[39m
[32m    678[39m     expr = expr.optimize()
[32m    679[39m     keys = [38;5;28mlist[39m(flatten(expr.__dask_keys__()))
[32m--> [39m[32m681[39m     results = [43mschedule[49m[43m([49m[43mexpr[49m[43m,[49m[43m [49m[43mkeys[49m[43m,[49m[43m [49m[43m*[49m[43m*[49m[43mkwargs[49m[43m)[49m
[32m    683[39m [38;5;28;01mreturn[39;00m repack(results)

[36mFile [39m[32m/home/conda/hytest/738ff346-1752093942-203-pangeo/lib/python3.11/site-packages/distributed/client.py:2409[39m, in [36mClient._gather[39m[34m(self, futures, errors, direct, local_worker)[39m
[32m   2407[39m     exception = st.exception
[32m   2408[39m     traceback = st.traceback
[32m-> [39m[32m2409[39m     [38;5;28;01mraise[39;00m exception.with_traceback(traceback)
[32m   2410[39m [38;5;28;01mif[39;00m errors == [33m"[39m[33mskip[39m[33m"[39m:
[32m   2411[39m     bad_keys.add(key)

[31mFutureCancelledError[39m: finalize-hlgfinalizecompute-82e609f9ddb04edf91235099b7b8d040 cancelled for reason: scheduler-connection-lost.
Client lost the connection to the scheduler. Please check your connection and re-run your work.

