Traceback (most recent call last):
  File "/home/conda/hytest/738ff346-1752093942-203-pangeo/lib/python3.11/site-packages/jupyter_core/utils/__init__.py", line 154, in wrapped
    asyncio.get_running_loop()
RuntimeError: no running event loop

During handling of the above exception, another exception occurred:

Traceback (most recent call last):
  File "/home/conda/hytest/738ff346-1752093942-203-pangeo/lib/python3.11/site-packages/jupyter_cache/executors/utils.py", line 58, in single_nb_execution
    executenb(
  File "/home/conda/hytest/738ff346-1752093942-203-pangeo/lib/python3.11/site-packages/nbclient/client.py", line 1319, in execute
    return NotebookClient(nb=nb, resources=resources, km=km, **kwargs).execute()
           ^^^^^^^^^^^^^^^^^^^^^^^^^^^^^^^^^^^^^^^^^^^^^^^^^^^^^^^^^^^^^^^^^^^^^
  File "/home/conda/hytest/738ff346-1752093942-203-pangeo/lib/python3.11/site-packages/jupyter_core/utils/__init__.py", line 158, in wrapped
    return loop.run_until_complete(inner)
           ^^^^^^^^^^^^^^^^^^^^^^^^^^^^^^
  File "/home/conda/hytest/738ff346-1752093942-203-pangeo/lib/python3.11/asyncio/base_events.py", line 654, in run_until_complete
    return future.result()
           ^^^^^^^^^^^^^^^
  File "/home/conda/hytest/738ff346-1752093942-203-pangeo/lib/python3.11/site-packages/nbclient/client.py", line 709, in async_execute
    await self.async_execute_cell(
  File "/home/conda/hytest/738ff346-1752093942-203-pangeo/lib/python3.11/site-packages/nbclient/client.py", line 1062, in async_execute_cell
    await self._check_raise_for_error(cell, cell_index, exec_reply)
  File "/home/conda/hytest/738ff346-1752093942-203-pangeo/lib/python3.11/site-packages/nbclient/client.py", line 918, in _check_raise_for_error
    raise CellExecutionError.from_cell_and_msg(cell, exec_reply_content)
nbclient.exceptions.CellExecutionError: An error occurred while executing the following cell:
------------------
import os
import graphviz
# Needed when boto3 >= 1.36.0 or the rechunking process will fail
# This needs to be set before the boto3 library gets loaded
# See: https://github.com/aws/aws-cli/issues/9214#issuecomment-2606619168
os.environ['AWS_REQUEST_CHECKSUM_CALCULATION'] = 'when_required'
os.environ['AWS_RESPONSE_CHECKSUM_VALIDATION'] = 'when_required'
------------------


[31m---------------------------------------------------------------------------[39m
[31mModuleNotFoundError[39m                       Traceback (most recent call last)
[36mCell[39m[36m [39m[32mIn[1][39m[32m, line 2[39m
[32m      1[39m [38;5;28;01mimport[39;00m[38;5;250m [39m[34;01mos[39;00m
[32m----> [39m[32m2[39m [38;5;28;01mimport[39;00m[38;5;250m [39m[34;01mgraphviz[39;00m
[32m      3[39m [38;5;66;03m# Needed when boto3 >= 1.36.0 or the rechunking process will fail[39;00m
[32m      4[39m [38;5;66;03m# This needs to be set before the boto3 library gets loaded[39;00m
[32m      5[39m [38;5;66;03m# See: https://github.com/aws/aws-cli/issues/9214#issuecomment-2606619168[39;00m
[32m      6[39m os.environ[[33m'[39m[33mAWS_REQUEST_CHECKSUM_CALCULATION[39m[33m'[39m] = [33m'[39m[33mwhen_required[39m[33m'[39m

[31mModuleNotFoundError[39m: No module named 'graphviz'

