Traceback (most recent call last):
  File "/home/conda/hytest/785d3670-1747942806-104-pangeo/lib/python3.12/site-packages/jupyter_cache/executors/utils.py", line 58, in single_nb_execution
    executenb(
  File "/home/conda/hytest/785d3670-1747942806-104-pangeo/lib/python3.12/site-packages/nbclient/client.py", line 1319, in execute
    return NotebookClient(nb=nb, resources=resources, km=km, **kwargs).execute()
           ^^^^^^^^^^^^^^^^^^^^^^^^^^^^^^^^^^^^^^^^^^^^^^^^^^^^^^^^^^^^^^^^^^^^^
  File "/home/conda/hytest/785d3670-1747942806-104-pangeo/lib/python3.12/site-packages/jupyter_core/utils/__init__.py", line 165, in wrapped
    return loop.run_until_complete(inner)
           ^^^^^^^^^^^^^^^^^^^^^^^^^^^^^^
  File "/home/conda/hytest/785d3670-1747942806-104-pangeo/lib/python3.12/asyncio/base_events.py", line 691, in run_until_complete
    return future.result()
           ^^^^^^^^^^^^^^^
  File "/home/conda/hytest/785d3670-1747942806-104-pangeo/lib/python3.12/site-packages/nbclient/client.py", line 709, in async_execute
    await self.async_execute_cell(
  File "/home/conda/hytest/785d3670-1747942806-104-pangeo/lib/python3.12/site-packages/nbclient/client.py", line 1062, in async_execute_cell
    await self._check_raise_for_error(cell, cell_index, exec_reply)
  File "/home/conda/hytest/785d3670-1747942806-104-pangeo/lib/python3.12/site-packages/nbclient/client.py", line 918, in _check_raise_for_error
    raise CellExecutionError.from_cell_and_msg(cell, exec_reply_content)
nbclient.exceptions.CellExecutionError: An error occurred while executing the following cell:
------------------
huc12_aggregation = xr.apply_ufunc(lambda data: data.todense(), huc12_aggregation)
------------------


[31mNameError[39m[31m:[39m name 'huc12_aggregation' is not defined


